{"cells":[{"cell_type":"code","execution_count":2,"metadata":{"colab":{"background_save":true,"base_uri":"https://localhost:8080/"},"executionInfo":{"elapsed":19465,"status":"ok","timestamp":1709251562366,"user":{"displayName":"Alan Chu","userId":"01538023754537267334"},"user_tz":360},"id":"DEsRCQlz-5Cx"},"outputs":[{"name":"stderr","output_type":"stream","text":["ERROR:root:Internal Python error in the inspect module.\n","Below is the traceback from this internal error.\n","\n","ERROR:root:Internal Python error in the inspect module.\n","Below is the traceback from this internal error.\n","\n","ERROR:root:Internal Python error in the inspect module.\n","Below is the traceback from this internal error.\n","\n"]},{"name":"stdout","output_type":"stream","text":["Mounted at /content/drive\n","Traceback (most recent call last):\n","  File \"/usr/local/lib/python3.10/dist-packages/IPython/core/interactiveshell.py\", line 3553, in run_code\n","    exec(code_obj, self.user_global_ns, self.user_ns)\n","  File \"\u003cipython-input-14-da9e96b6d31b\u003e\", line 8, in \u003ccell line: 8\u003e\n","    get_ipython().run_line_magic('cd', 'drive/MyDrive/$FOLDERNAME')\n","  File \"/usr/local/lib/python3.10/dist-packages/IPython/core/interactiveshell.py\", line 2418, in run_line_magic\n","    result = fn(*args, **kwargs)\n","  File \"\u003cdecorator-gen-85\u003e\", line 2, in cd\n","  File \"/usr/local/lib/python3.10/dist-packages/IPython/core/magic.py\", line 187, in \u003clambda\u003e\n","    call = lambda f, *a, **k: f(*a, **k)\n","  File \"/usr/local/lib/python3.10/dist-packages/IPython/core/magics/osm.py\", line 342, in cd\n","    oldcwd = os.getcwd()\n","OSError: [Errno 107] Transport endpoint is not connected\n","\n","During handling of the above exception, another exception occurred:\n","\n","Traceback (most recent call last):\n","  File \"/usr/local/lib/python3.10/dist-packages/IPython/core/interactiveshell.py\", line 2099, in showtraceback\n","    stb = value._render_traceback_()\n","AttributeError: 'OSError' object has no attribute '_render_traceback_'\n","\n","During handling of the above exception, another exception occurred:\n","\n","Traceback (most recent call last):\n","  File \"/usr/local/lib/python3.10/dist-packages/IPython/core/ultratb.py\", line 1101, in get_records\n","    return _fixed_getinnerframes(etb, number_of_lines_of_context, tb_offset)\n","  File \"/usr/local/lib/python3.10/dist-packages/IPython/core/ultratb.py\", line 248, in wrapped\n","    return f(*args, **kwargs)\n","  File \"/usr/local/lib/python3.10/dist-packages/IPython/core/ultratb.py\", line 281, in _fixed_getinnerframes\n","    records = fix_frame_records_filenames(inspect.getinnerframes(etb, context))\n","  File \"/usr/lib/python3.10/inspect.py\", line 1662, in getinnerframes\n","    frameinfo = (tb.tb_frame,) + getframeinfo(tb, context)\n","  File \"/usr/lib/python3.10/inspect.py\", line 1620, in getframeinfo\n","    filename = getsourcefile(frame) or getfile(frame)\n","  File \"/usr/lib/python3.10/inspect.py\", line 829, in getsourcefile\n","    module = getmodule(object, filename)\n","  File \"/usr/lib/python3.10/inspect.py\", line 861, in getmodule\n","    file = getabsfile(object, _filename)\n","  File \"/usr/lib/python3.10/inspect.py\", line 845, in getabsfile\n","    return os.path.normcase(os.path.abspath(_filename))\n","  File \"/usr/lib/python3.10/posixpath.py\", line 384, in abspath\n","    cwd = os.getcwd()\n","OSError: [Errno 107] Transport endpoint is not connected\n","Traceback (most recent call last):\n","  File \"/usr/local/lib/python3.10/dist-packages/IPython/core/interactiveshell.py\", line 3553, in run_code\n","    exec(code_obj, self.user_global_ns, self.user_ns)\n","  File \"\u003cipython-input-14-da9e96b6d31b\u003e\", line 8, in \u003ccell line: 8\u003e\n","    get_ipython().run_line_magic('cd', 'drive/MyDrive/$FOLDERNAME')\n","  File \"/usr/local/lib/python3.10/dist-packages/IPython/core/interactiveshell.py\", line 2418, in run_line_magic\n","    result = fn(*args, **kwargs)\n","  File \"\u003cdecorator-gen-85\u003e\", line 2, in cd\n","  File \"/usr/local/lib/python3.10/dist-packages/IPython/core/magic.py\", line 187, in \u003clambda\u003e\n","    call = lambda f, *a, **k: f(*a, **k)\n","  File \"/usr/local/lib/python3.10/dist-packages/IPython/core/magics/osm.py\", line 342, in cd\n","    oldcwd = os.getcwd()\n","OSError: [Errno 107] Transport endpoint is not connected\n","\n","During handling of the above exception, another exception occurred:\n","\n","Traceback (most recent call last):\n","  File \"/usr/local/lib/python3.10/dist-packages/IPython/core/interactiveshell.py\", line 2099, in showtraceback\n","    stb = value._render_traceback_()\n","AttributeError: 'OSError' object has no attribute '_render_traceback_'\n","\n","During handling of the above exception, another exception occurred:\n","\n","Traceback (most recent call last):\n","  File \"/usr/local/lib/python3.10/dist-packages/IPython/core/interactiveshell.py\", line 3473, in run_ast_nodes\n","    if (await self.run_code(code, result,  async_=asy)):\n","  File \"/usr/local/lib/python3.10/dist-packages/IPython/core/interactiveshell.py\", line 3575, in run_code\n","    self.showtraceback(running_compiled_code=True)\n","  File \"/usr/local/lib/python3.10/dist-packages/IPython/core/interactiveshell.py\", line 2101, in showtraceback\n","    stb = self.InteractiveTB.structured_traceback(etype,\n","  File \"/usr/local/lib/python3.10/dist-packages/IPython/core/ultratb.py\", line 1367, in structured_traceback\n","    return FormattedTB.structured_traceback(\n","  File \"/usr/local/lib/python3.10/dist-packages/IPython/core/ultratb.py\", line 1267, in structured_traceback\n","    return VerboseTB.structured_traceback(\n","  File \"/usr/local/lib/python3.10/dist-packages/IPython/core/ultratb.py\", line 1124, in structured_traceback\n","    formatted_exception = self.format_exception_as_a_whole(etype, evalue, etb, number_of_lines_of_context,\n","  File \"/usr/local/lib/python3.10/dist-packages/IPython/core/ultratb.py\", line 1082, in format_exception_as_a_whole\n","    last_unique, recursion_repeat = find_recursion(orig_etype, evalue, records)\n","  File \"/usr/local/lib/python3.10/dist-packages/IPython/core/ultratb.py\", line 382, in find_recursion\n","    return len(records), 0\n","TypeError: object of type 'NoneType' has no len()\n","\n","During handling of the above exception, another exception occurred:\n","\n","Traceback (most recent call last):\n","  File \"/usr/local/lib/python3.10/dist-packages/IPython/core/interactiveshell.py\", line 2099, in showtraceback\n","    stb = value._render_traceback_()\n","AttributeError: 'TypeError' object has no attribute '_render_traceback_'\n","\n","During handling of the above exception, another exception occurred:\n","\n","Traceback (most recent call last):\n","  File \"/usr/local/lib/python3.10/dist-packages/IPython/core/ultratb.py\", line 1101, in get_records\n","    return _fixed_getinnerframes(etb, number_of_lines_of_context, tb_offset)\n","  File \"/usr/local/lib/python3.10/dist-packages/IPython/core/ultratb.py\", line 248, in wrapped\n","    return f(*args, **kwargs)\n","  File \"/usr/local/lib/python3.10/dist-packages/IPython/core/ultratb.py\", line 281, in _fixed_getinnerframes\n","    records = fix_frame_records_filenames(inspect.getinnerframes(etb, context))\n","  File \"/usr/lib/python3.10/inspect.py\", line 1662, in getinnerframes\n","    frameinfo = (tb.tb_frame,) + getframeinfo(tb, context)\n","  File \"/usr/lib/python3.10/inspect.py\", line 1620, in getframeinfo\n","    filename = getsourcefile(frame) or getfile(frame)\n","  File \"/usr/lib/python3.10/inspect.py\", line 829, in getsourcefile\n","    module = getmodule(object, filename)\n","  File \"/usr/lib/python3.10/inspect.py\", line 861, in getmodule\n","    file = getabsfile(object, _filename)\n","  File \"/usr/lib/python3.10/inspect.py\", line 845, in getabsfile\n","    return os.path.normcase(os.path.abspath(_filename))\n","  File \"/usr/lib/python3.10/posixpath.py\", line 384, in abspath\n","    cwd = os.getcwd()\n","OSError: [Errno 107] Transport endpoint is not connected\n","Traceback (most recent call last):\n","  File \"/usr/local/lib/python3.10/dist-packages/IPython/core/interactiveshell.py\", line 3553, in run_code\n","    exec(code_obj, self.user_global_ns, self.user_ns)\n","  File \"\u003cipython-input-14-da9e96b6d31b\u003e\", line 8, in \u003ccell line: 8\u003e\n","    get_ipython().run_line_magic('cd', 'drive/MyDrive/$FOLDERNAME')\n","  File \"/usr/local/lib/python3.10/dist-packages/IPython/core/interactiveshell.py\", line 2418, in run_line_magic\n","    result = fn(*args, **kwargs)\n","  File \"\u003cdecorator-gen-85\u003e\", line 2, in cd\n","  File \"/usr/local/lib/python3.10/dist-packages/IPython/core/magic.py\", line 187, in \u003clambda\u003e\n","    call = lambda f, *a, **k: f(*a, **k)\n","  File \"/usr/local/lib/python3.10/dist-packages/IPython/core/magics/osm.py\", line 342, in cd\n","    oldcwd = os.getcwd()\n","OSError: [Errno 107] Transport endpoint is not connected\n","\n","During handling of the above exception, another exception occurred:\n","\n","Traceback (most recent call last):\n","  File \"/usr/local/lib/python3.10/dist-packages/IPython/core/interactiveshell.py\", line 2099, in showtraceback\n","    stb = value._render_traceback_()\n","AttributeError: 'OSError' object has no attribute '_render_traceback_'\n","\n","During handling of the above exception, another exception occurred:\n","\n","Traceback (most recent call last):\n","  File \"/usr/local/lib/python3.10/dist-packages/IPython/core/interactiveshell.py\", line 3473, in run_ast_nodes\n","    if (await self.run_code(code, result,  async_=asy)):\n","  File \"/usr/local/lib/python3.10/dist-packages/IPython/core/interactiveshell.py\", line 3575, in run_code\n","    self.showtraceback(running_compiled_code=True)\n","  File \"/usr/local/lib/python3.10/dist-packages/IPython/core/interactiveshell.py\", line 2101, in showtraceback\n","    stb = self.InteractiveTB.structured_traceback(etype,\n","  File \"/usr/local/lib/python3.10/dist-packages/IPython/core/ultratb.py\", line 1367, in structured_traceback\n","    return FormattedTB.structured_traceback(\n","  File \"/usr/local/lib/python3.10/dist-packages/IPython/core/ultratb.py\", line 1267, in structured_traceback\n","    return VerboseTB.structured_traceback(\n","  File \"/usr/local/lib/python3.10/dist-packages/IPython/core/ultratb.py\", line 1124, in structured_traceback\n","    formatted_exception = self.format_exception_as_a_whole(etype, evalue, etb, number_of_lines_of_context,\n","  File \"/usr/local/lib/python3.10/dist-packages/IPython/core/ultratb.py\", line 1082, in format_exception_as_a_whole\n","    last_unique, recursion_repeat = find_recursion(orig_etype, evalue, records)\n","  File \"/usr/local/lib/python3.10/dist-packages/IPython/core/ultratb.py\", line 382, in find_recursion\n","    return len(records), 0\n","TypeError: object of type 'NoneType' has no len()\n","\n","During handling of the above exception, another exception occurred:\n","\n","Traceback (most recent call last):\n","  File \"/usr/local/lib/python3.10/dist-packages/IPython/core/interactiveshell.py\", line 2099, in showtraceback\n","    stb = value._render_traceback_()\n","AttributeError: 'TypeError' object has no attribute '_render_traceback_'\n","\n","During handling of the above exception, another exception occurred:\n","\n","Traceback (most recent call last):\n","  File \"/usr/local/lib/python3.10/dist-packages/IPython/core/interactiveshell.py\", line 3030, in _run_cell\n","    return runner(coro)\n","  File \"/usr/local/lib/python3.10/dist-packages/IPython/core/async_helpers.py\", line 78, in _pseudo_sync_runner\n","    coro.send(None)\n","  File \"/usr/local/lib/python3.10/dist-packages/IPython/core/interactiveshell.py\", line 3257, in run_cell_async\n","    has_raised = await self.run_ast_nodes(code_ast.body, cell_name,\n","  File \"/usr/local/lib/python3.10/dist-packages/IPython/core/interactiveshell.py\", line 3492, in run_ast_nodes\n","    self.showtraceback()\n","  File \"/usr/local/lib/python3.10/dist-packages/IPython/core/interactiveshell.py\", line 2101, in showtraceback\n","    stb = self.InteractiveTB.structured_traceback(etype,\n","  File \"/usr/local/lib/python3.10/dist-packages/IPython/core/ultratb.py\", line 1367, in structured_traceback\n","    return FormattedTB.structured_traceback(\n","  File \"/usr/local/lib/python3.10/dist-packages/IPython/core/ultratb.py\", line 1267, in structured_traceback\n","    return VerboseTB.structured_traceback(\n","  File \"/usr/local/lib/python3.10/dist-packages/IPython/core/ultratb.py\", line 1142, in structured_traceback\n","    formatted_exceptions += self.format_exception_as_a_whole(etype, evalue, etb, lines_of_context,\n","  File \"/usr/local/lib/python3.10/dist-packages/IPython/core/ultratb.py\", line 1082, in format_exception_as_a_whole\n","    last_unique, recursion_repeat = find_recursion(orig_etype, evalue, records)\n","  File \"/usr/local/lib/python3.10/dist-packages/IPython/core/ultratb.py\", line 382, in find_recursion\n","    return len(records), 0\n","TypeError: object of type 'NoneType' has no len()\n","\n","During handling of the above exception, another exception occurred:\n","\n","Traceback (most recent call last):\n","  File \"/usr/local/lib/python3.10/dist-packages/IPython/core/interactiveshell.py\", line 2099, in showtraceback\n","    stb = value._render_traceback_()\n","AttributeError: 'TypeError' object has no attribute '_render_traceback_'\n","\n","During handling of the above exception, another exception occurred:\n","\n","Traceback (most recent call last):\n","  File \"/usr/local/lib/python3.10/dist-packages/IPython/core/ultratb.py\", line 1101, in get_records\n","    return _fixed_getinnerframes(etb, number_of_lines_of_context, tb_offset)\n","  File \"/usr/local/lib/python3.10/dist-packages/IPython/core/ultratb.py\", line 248, in wrapped\n","    return f(*args, **kwargs)\n","  File \"/usr/local/lib/python3.10/dist-packages/IPython/core/ultratb.py\", line 281, in _fixed_getinnerframes\n","    records = fix_frame_records_filenames(inspect.getinnerframes(etb, context))\n","  File \"/usr/lib/python3.10/inspect.py\", line 1662, in getinnerframes\n","    frameinfo = (tb.tb_frame,) + getframeinfo(tb, context)\n","  File \"/usr/lib/python3.10/inspect.py\", line 1620, in getframeinfo\n","    filename = getsourcefile(frame) or getfile(frame)\n","  File \"/usr/lib/python3.10/inspect.py\", line 829, in getsourcefile\n","    module = getmodule(object, filename)\n","  File \"/usr/lib/python3.10/inspect.py\", line 861, in getmodule\n","    file = getabsfile(object, _filename)\n","  File \"/usr/lib/python3.10/inspect.py\", line 845, in getabsfile\n","    return os.path.normcase(os.path.abspath(_filename))\n","  File \"/usr/lib/python3.10/posixpath.py\", line 384, in abspath\n","    cwd = os.getcwd()\n","OSError: [Errno 107] Transport endpoint is not connected\n"]}],"source":["# Mount to Google Drive\n","from google.colab import drive\n","drive.mount('/content/drive', force_remount=True)\n","\n","# Define Project Folder\n","FOLDERNAME = 'Colab\\ Notebooks/SC201L16'\n","\n","%cd drive/MyDrive/$FOLDERNAME"]},{"cell_type":"code","execution_count":3,"metadata":{"colab":{"base_uri":"https://localhost:8080/"},"executionInfo":{"elapsed":3,"status":"ok","timestamp":1709251562500,"user":{"displayName":"Alan Chu","userId":"01538023754537267334"},"user_tz":360},"id":"pUvgKcdC_PlB","outputId":"acc5b6c0-014f-4c5c-ffbf-929a7372e2d5"},"outputs":[{"name":"stdout","output_type":"stream","text":["Device: cuda\n"]}],"source":["# Define device\n","import torch\n","if torch.cuda.is_available():\n","  device = torch.device('cuda')\n","else:\n","  device = torch.device('cpu')\n","print('Device:', device)"]},{"cell_type":"code","execution_count":4,"metadata":{"colab":{"background_save":true},"executionInfo":{"elapsed":6460,"status":"ok","timestamp":1709251568959,"user":{"displayName":"Alan Chu","userId":"01538023754537267334"},"user_tz":360},"id":"5WXam8AA_bXa"},"outputs":[{"name":"stderr","output_type":"stream","text":["ERROR:root:Internal Python error in the inspect module.\n","Below is the traceback from this internal error.\n","\n","ERROR:root:Internal Python error in the inspect module.\n","Below is the traceback from this internal error.\n","\n","ERROR:root:Internal Python error in the inspect module.\n","Below is the traceback from this internal error.\n","\n"]},{"name":"stdout","output_type":"stream","text":["Traceback (most recent call last):\n","  File \"/usr/local/lib/python3.10/dist-packages/IPython/core/interactiveshell.py\", line 3553, in run_code\n","    exec(code_obj, self.user_global_ns, self.user_ns)\n","  File \"\u003cipython-input-15-1815dd68026e\u003e\", line 5, in \u003ccell line: 5\u003e\n","    train_data = dset.MNIST('./train',train=True,download=True,transform=transform)\n","  File \"/usr/local/lib/python3.10/dist-packages/torchvision/datasets/mnist.py\", line 99, in __init__\n","    self.download()\n","  File \"/usr/local/lib/python3.10/dist-packages/torchvision/datasets/mnist.py\", line 179, in download\n","    os.makedirs(self.raw_folder, exist_ok=True)\n","  File \"/usr/lib/python3.10/os.py\", line 215, in makedirs\n","    makedirs(head, exist_ok=exist_ok)\n","  File \"/usr/lib/python3.10/os.py\", line 215, in makedirs\n","    makedirs(head, exist_ok=exist_ok)\n","  File \"/usr/lib/python3.10/os.py\", line 225, in makedirs\n","    mkdir(name, mode)\n","OSError: [Errno 107] Transport endpoint is not connected: './train'\n","\n","During handling of the above exception, another exception occurred:\n","\n","Traceback (most recent call last):\n","  File \"/usr/local/lib/python3.10/dist-packages/IPython/core/interactiveshell.py\", line 2099, in showtraceback\n","    stb = value._render_traceback_()\n","AttributeError: 'OSError' object has no attribute '_render_traceback_'\n","\n","During handling of the above exception, another exception occurred:\n","\n","Traceback (most recent call last):\n","  File \"/usr/local/lib/python3.10/dist-packages/IPython/core/ultratb.py\", line 1101, in get_records\n","    return _fixed_getinnerframes(etb, number_of_lines_of_context, tb_offset)\n","  File \"/usr/local/lib/python3.10/dist-packages/IPython/core/ultratb.py\", line 248, in wrapped\n","    return f(*args, **kwargs)\n","  File \"/usr/local/lib/python3.10/dist-packages/IPython/core/ultratb.py\", line 281, in _fixed_getinnerframes\n","    records = fix_frame_records_filenames(inspect.getinnerframes(etb, context))\n","  File \"/usr/lib/python3.10/inspect.py\", line 1662, in getinnerframes\n","    frameinfo = (tb.tb_frame,) + getframeinfo(tb, context)\n","  File \"/usr/lib/python3.10/inspect.py\", line 1620, in getframeinfo\n","    filename = getsourcefile(frame) or getfile(frame)\n","  File \"/usr/lib/python3.10/inspect.py\", line 829, in getsourcefile\n","    module = getmodule(object, filename)\n","  File \"/usr/lib/python3.10/inspect.py\", line 861, in getmodule\n","    file = getabsfile(object, _filename)\n","  File \"/usr/lib/python3.10/inspect.py\", line 845, in getabsfile\n","    return os.path.normcase(os.path.abspath(_filename))\n","  File \"/usr/lib/python3.10/posixpath.py\", line 384, in abspath\n","    cwd = os.getcwd()\n","OSError: [Errno 107] Transport endpoint is not connected\n","Traceback (most recent call last):\n","  File \"/usr/local/lib/python3.10/dist-packages/IPython/core/interactiveshell.py\", line 3553, in run_code\n","    exec(code_obj, self.user_global_ns, self.user_ns)\n","  File \"\u003cipython-input-15-1815dd68026e\u003e\", line 5, in \u003ccell line: 5\u003e\n","    train_data = dset.MNIST('./train',train=True,download=True,transform=transform)\n","  File \"/usr/local/lib/python3.10/dist-packages/torchvision/datasets/mnist.py\", line 99, in __init__\n","    self.download()\n","  File \"/usr/local/lib/python3.10/dist-packages/torchvision/datasets/mnist.py\", line 179, in download\n","    os.makedirs(self.raw_folder, exist_ok=True)\n","  File \"/usr/lib/python3.10/os.py\", line 215, in makedirs\n","    makedirs(head, exist_ok=exist_ok)\n","  File \"/usr/lib/python3.10/os.py\", line 215, in makedirs\n","    makedirs(head, exist_ok=exist_ok)\n","  File \"/usr/lib/python3.10/os.py\", line 225, in makedirs\n","    mkdir(name, mode)\n","OSError: [Errno 107] Transport endpoint is not connected: './train'\n","\n","During handling of the above exception, another exception occurred:\n","\n","Traceback (most recent call last):\n","  File \"/usr/local/lib/python3.10/dist-packages/IPython/core/interactiveshell.py\", line 2099, in showtraceback\n","    stb = value._render_traceback_()\n","AttributeError: 'OSError' object has no attribute '_render_traceback_'\n","\n","During handling of the above exception, another exception occurred:\n","\n","Traceback (most recent call last):\n","  File \"/usr/local/lib/python3.10/dist-packages/IPython/core/interactiveshell.py\", line 3473, in run_ast_nodes\n","    if (await self.run_code(code, result,  async_=asy)):\n","  File \"/usr/local/lib/python3.10/dist-packages/IPython/core/interactiveshell.py\", line 3575, in run_code\n","    self.showtraceback(running_compiled_code=True)\n","  File \"/usr/local/lib/python3.10/dist-packages/IPython/core/interactiveshell.py\", line 2101, in showtraceback\n","    stb = self.InteractiveTB.structured_traceback(etype,\n","  File \"/usr/local/lib/python3.10/dist-packages/IPython/core/ultratb.py\", line 1367, in structured_traceback\n","    return FormattedTB.structured_traceback(\n","  File \"/usr/local/lib/python3.10/dist-packages/IPython/core/ultratb.py\", line 1267, in structured_traceback\n","    return VerboseTB.structured_traceback(\n","  File \"/usr/local/lib/python3.10/dist-packages/IPython/core/ultratb.py\", line 1124, in structured_traceback\n","    formatted_exception = self.format_exception_as_a_whole(etype, evalue, etb, number_of_lines_of_context,\n","  File \"/usr/local/lib/python3.10/dist-packages/IPython/core/ultratb.py\", line 1082, in format_exception_as_a_whole\n","    last_unique, recursion_repeat = find_recursion(orig_etype, evalue, records)\n","  File \"/usr/local/lib/python3.10/dist-packages/IPython/core/ultratb.py\", line 382, in find_recursion\n","    return len(records), 0\n","TypeError: object of type 'NoneType' has no len()\n","\n","During handling of the above exception, another exception occurred:\n","\n","Traceback (most recent call last):\n","  File \"/usr/local/lib/python3.10/dist-packages/IPython/core/interactiveshell.py\", line 2099, in showtraceback\n","    stb = value._render_traceback_()\n","AttributeError: 'TypeError' object has no attribute '_render_traceback_'\n","\n","During handling of the above exception, another exception occurred:\n","\n","Traceback (most recent call last):\n","  File \"/usr/local/lib/python3.10/dist-packages/IPython/core/ultratb.py\", line 1101, in get_records\n","    return _fixed_getinnerframes(etb, number_of_lines_of_context, tb_offset)\n","  File \"/usr/local/lib/python3.10/dist-packages/IPython/core/ultratb.py\", line 248, in wrapped\n","    return f(*args, **kwargs)\n","  File \"/usr/local/lib/python3.10/dist-packages/IPython/core/ultratb.py\", line 281, in _fixed_getinnerframes\n","    records = fix_frame_records_filenames(inspect.getinnerframes(etb, context))\n","  File \"/usr/lib/python3.10/inspect.py\", line 1662, in getinnerframes\n","    frameinfo = (tb.tb_frame,) + getframeinfo(tb, context)\n","  File \"/usr/lib/python3.10/inspect.py\", line 1620, in getframeinfo\n","    filename = getsourcefile(frame) or getfile(frame)\n","  File \"/usr/lib/python3.10/inspect.py\", line 829, in getsourcefile\n","    module = getmodule(object, filename)\n","  File \"/usr/lib/python3.10/inspect.py\", line 861, in getmodule\n","    file = getabsfile(object, _filename)\n","  File \"/usr/lib/python3.10/inspect.py\", line 845, in getabsfile\n","    return os.path.normcase(os.path.abspath(_filename))\n","  File \"/usr/lib/python3.10/posixpath.py\", line 384, in abspath\n","    cwd = os.getcwd()\n","OSError: [Errno 107] Transport endpoint is not connected\n","Traceback (most recent call last):\n","  File \"/usr/local/lib/python3.10/dist-packages/IPython/core/interactiveshell.py\", line 3553, in run_code\n","    exec(code_obj, self.user_global_ns, self.user_ns)\n","  File \"\u003cipython-input-15-1815dd68026e\u003e\", line 5, in \u003ccell line: 5\u003e\n","    train_data = dset.MNIST('./train',train=True,download=True,transform=transform)\n","  File \"/usr/local/lib/python3.10/dist-packages/torchvision/datasets/mnist.py\", line 99, in __init__\n","    self.download()\n","  File \"/usr/local/lib/python3.10/dist-packages/torchvision/datasets/mnist.py\", line 179, in download\n","    os.makedirs(self.raw_folder, exist_ok=True)\n","  File \"/usr/lib/python3.10/os.py\", line 215, in makedirs\n","    makedirs(head, exist_ok=exist_ok)\n","  File \"/usr/lib/python3.10/os.py\", line 215, in makedirs\n","    makedirs(head, exist_ok=exist_ok)\n","  File \"/usr/lib/python3.10/os.py\", line 225, in makedirs\n","    mkdir(name, mode)\n","OSError: [Errno 107] Transport endpoint is not connected: './train'\n","\n","During handling of the above exception, another exception occurred:\n","\n","Traceback (most recent call last):\n","  File \"/usr/local/lib/python3.10/dist-packages/IPython/core/interactiveshell.py\", line 2099, in showtraceback\n","    stb = value._render_traceback_()\n","AttributeError: 'OSError' object has no attribute '_render_traceback_'\n","\n","During handling of the above exception, another exception occurred:\n","\n","Traceback (most recent call last):\n","  File \"/usr/local/lib/python3.10/dist-packages/IPython/core/interactiveshell.py\", line 3473, in run_ast_nodes\n","    if (await self.run_code(code, result,  async_=asy)):\n","  File \"/usr/local/lib/python3.10/dist-packages/IPython/core/interactiveshell.py\", line 3575, in run_code\n","    self.showtraceback(running_compiled_code=True)\n","  File \"/usr/local/lib/python3.10/dist-packages/IPython/core/interactiveshell.py\", line 2101, in showtraceback\n","    stb = self.InteractiveTB.structured_traceback(etype,\n","  File \"/usr/local/lib/python3.10/dist-packages/IPython/core/ultratb.py\", line 1367, in structured_traceback\n","    return FormattedTB.structured_traceback(\n","  File \"/usr/local/lib/python3.10/dist-packages/IPython/core/ultratb.py\", line 1267, in structured_traceback\n","    return VerboseTB.structured_traceback(\n","  File \"/usr/local/lib/python3.10/dist-packages/IPython/core/ultratb.py\", line 1124, in structured_traceback\n","    formatted_exception = self.format_exception_as_a_whole(etype, evalue, etb, number_of_lines_of_context,\n","  File \"/usr/local/lib/python3.10/dist-packages/IPython/core/ultratb.py\", line 1082, in format_exception_as_a_whole\n","    last_unique, recursion_repeat = find_recursion(orig_etype, evalue, records)\n","  File \"/usr/local/lib/python3.10/dist-packages/IPython/core/ultratb.py\", line 382, in find_recursion\n","    return len(records), 0\n","TypeError: object of type 'NoneType' has no len()\n","\n","During handling of the above exception, another exception occurred:\n","\n","Traceback (most recent call last):\n","  File \"/usr/local/lib/python3.10/dist-packages/IPython/core/interactiveshell.py\", line 2099, in showtraceback\n","    stb = value._render_traceback_()\n","AttributeError: 'TypeError' object has no attribute '_render_traceback_'\n","\n","During handling of the above exception, another exception occurred:\n","\n","Traceback (most recent call last):\n","  File \"/usr/local/lib/python3.10/dist-packages/IPython/core/interactiveshell.py\", line 3030, in _run_cell\n","    return runner(coro)\n","  File \"/usr/local/lib/python3.10/dist-packages/IPython/core/async_helpers.py\", line 78, in _pseudo_sync_runner\n","    coro.send(None)\n","  File \"/usr/local/lib/python3.10/dist-packages/IPython/core/interactiveshell.py\", line 3257, in run_cell_async\n","    has_raised = await self.run_ast_nodes(code_ast.body, cell_name,\n","  File \"/usr/local/lib/python3.10/dist-packages/IPython/core/interactiveshell.py\", line 3492, in run_ast_nodes\n","    self.showtraceback()\n","  File \"/usr/local/lib/python3.10/dist-packages/IPython/core/interactiveshell.py\", line 2101, in showtraceback\n","    stb = self.InteractiveTB.structured_traceback(etype,\n","  File \"/usr/local/lib/python3.10/dist-packages/IPython/core/ultratb.py\", line 1367, in structured_traceback\n","    return FormattedTB.structured_traceback(\n","  File \"/usr/local/lib/python3.10/dist-packages/IPython/core/ultratb.py\", line 1267, in structured_traceback\n","    return VerboseTB.structured_traceback(\n","  File \"/usr/local/lib/python3.10/dist-packages/IPython/core/ultratb.py\", line 1142, in structured_traceback\n","    formatted_exceptions += self.format_exception_as_a_whole(etype, evalue, etb, lines_of_context,\n","  File \"/usr/local/lib/python3.10/dist-packages/IPython/core/ultratb.py\", line 1082, in format_exception_as_a_whole\n","    last_unique, recursion_repeat = find_recursion(orig_etype, evalue, records)\n","  File \"/usr/local/lib/python3.10/dist-packages/IPython/core/ultratb.py\", line 382, in find_recursion\n","    return len(records), 0\n","TypeError: object of type 'NoneType' has no len()\n","\n","During handling of the above exception, another exception occurred:\n","\n","Traceback (most recent call last):\n","  File \"/usr/local/lib/python3.10/dist-packages/IPython/core/interactiveshell.py\", line 2099, in showtraceback\n","    stb = value._render_traceback_()\n","AttributeError: 'TypeError' object has no attribute '_render_traceback_'\n","\n","During handling of the above exception, another exception occurred:\n","\n","Traceback (most recent call last):\n","  File \"/usr/local/lib/python3.10/dist-packages/IPython/core/ultratb.py\", line 1101, in get_records\n","    return _fixed_getinnerframes(etb, number_of_lines_of_context, tb_offset)\n","  File \"/usr/local/lib/python3.10/dist-packages/IPython/core/ultratb.py\", line 248, in wrapped\n","    return f(*args, **kwargs)\n","  File \"/usr/local/lib/python3.10/dist-packages/IPython/core/ultratb.py\", line 281, in _fixed_getinnerframes\n","    records = fix_frame_records_filenames(inspect.getinnerframes(etb, context))\n","  File \"/usr/lib/python3.10/inspect.py\", line 1662, in getinnerframes\n","    frameinfo = (tb.tb_frame,) + getframeinfo(tb, context)\n","  File \"/usr/lib/python3.10/inspect.py\", line 1620, in getframeinfo\n","    filename = getsourcefile(frame) or getfile(frame)\n","  File \"/usr/lib/python3.10/inspect.py\", line 829, in getsourcefile\n","    module = getmodule(object, filename)\n","  File \"/usr/lib/python3.10/inspect.py\", line 861, in getmodule\n","    file = getabsfile(object, _filename)\n","  File \"/usr/lib/python3.10/inspect.py\", line 845, in getabsfile\n","    return os.path.normcase(os.path.abspath(_filename))\n","  File \"/usr/lib/python3.10/posixpath.py\", line 384, in abspath\n","    cwd = os.getcwd()\n","OSError: [Errno 107] Transport endpoint is not connected\n"]}],"source":["# Load Existing Dataset\n","import torchvision.datasets as dset\n","import torchvision.transforms as T\n","transform = T.Compose([T.ToTensor(),T.RandomAutocontrast()])\n","train_data = dset.MNIST('./train',train=True,download=True,transform=transform)\n","val_data = dset.MNIST('./val',train=False,download=True,transform=transform)"]},{"cell_type":"code","execution_count":5,"metadata":{"colab":{"base_uri":"https://localhost:8080/"},"executionInfo":{"elapsed":22,"status":"ok","timestamp":1709251568959,"user":{"displayName":"Alan Chu","userId":"01538023754537267334"},"user_tz":360},"id":"BUYRd7bfKy7N","outputId":"9cac16f2-c32d-448a-d6a1-850278ed1f4f"},"outputs":[{"name":"stdout","output_type":"stream","text":["Dataset MNIST\n","    Number of datapoints: 60000\n","    Root location: ./train\n","    Split: Train\n","    StandardTransform\n","Transform: Compose(\n","               ToTensor()\n","               RandomAutocontrast(p=0.5)\n","           )\n"]}],"source":["# Check Data Dimension\n","print(train_data)"]},{"cell_type":"code","execution_count":6,"metadata":{"colab":{"base_uri":"https://localhost:8080/"},"executionInfo":{"elapsed":19,"status":"ok","timestamp":1709251568959,"user":{"displayName":"Alan Chu","userId":"01538023754537267334"},"user_tz":360},"id":"XU1jEieB6cqz","outputId":"ff326677-3543-40c7-865f-dfa740ea0b6a"},"outputs":[{"data":{"text/plain":["torch.Size([1, 28, 28])"]},"execution_count":6,"metadata":{},"output_type":"execute_result"}],"source":["\n","train_data[0][0].shape ## print data"]},{"cell_type":"code","execution_count":7,"metadata":{"colab":{"base_uri":"https://localhost:8080/"},"executionInfo":{"elapsed":16,"status":"ok","timestamp":1709251568959,"user":{"displayName":"Alan Chu","userId":"01538023754537267334"},"user_tz":360},"id":"KB8ZyWY5EQTS","outputId":"ffe3ed6f-d473-4b5e-958f-880e387c93dd"},"outputs":[{"name":"stdout","output_type":"stream","text":["Number of training: 60000\n","Number of validation: 10000\n"]}],"source":["num_train = len(train_data)\n","num_val = len(val_data)\n","print('Number of training:', num_train)\n","print('Number of validation:', num_val)"]},{"cell_type":"code","execution_count":1,"metadata":{"executionInfo":{"elapsed":4453,"status":"ok","timestamp":1709251542903,"user":{"displayName":"Alan Chu","userId":"01538023754537267334"},"user_tz":360},"id":"QTFFEk6xAJ99"},"outputs":[],"source":["# Build Model\n","import torch.nn as nn\n","model = None\n","# model = nn.Sequential(\n","#     # N x 1 x 28 x 28\n","\n","#     nn.Conv2d(in_channels=1,out_channels=64,kernel_size=3,padding=1,stride =1),\n","#     nn.BatchNorm2d(num_features=64),\n","#     nn.ReLU(),\n","#     nn.MaxPool2d(kernel_size=2,stride=2),\n","#     # 16 x 64 x 14 x 14\n","\n","#     nn.Flatten(),\n","#     # 10 neurons(0-9)\n","#     nn.Linear(64*14*14,10)\n","# )\n","class MyModel(nn.Module):\n","  def __init__(self):\n","    super().__init__()\n","    self.conv2d = nn.Conv2d(1,64,3,1,1)\n","    self.bn2d = nn.BatchNorm2d(64)\n","    self.fc = nn.Linear(64*14*14,10)\n","\n","  def forward(self,x):\n","    out = self.conv2d(x)\n","    out = self.bn2d(out)\n","    out = nn.functional.relu(out)\n","    out = nn.functional.max_pool2d(out,(2,2))\n","    out = self.fc(out)\n","    return out\n","model = MyModel()"]},{"cell_type":"code","execution_count":8,"metadata":{"executionInfo":{"elapsed":409,"status":"ok","timestamp":1709251569354,"user":{"displayName":"Alan Chu","userId":"01538023754537267334"},"user_tz":360},"id":"wTg71OLVKaIO"},"outputs":[],"source":["# Move model to GPU\n","# -\u003e GPU\n","model = model.cuda()"]},{"cell_type":"code","execution_count":9,"metadata":{"executionInfo":{"elapsed":3,"status":"ok","timestamp":1709251569354,"user":{"displayName":"Alan Chu","userId":"01538023754537267334"},"user_tz":360},"id":"jbGU1OaCAfnE"},"outputs":[],"source":["# Create Mini-batches\n","from torch.utils.data import DataLoader\n","mini_trains = DataLoader(train_data, batch_size=128, shuffle=True)\n","mini_vals = DataLoader(val_data, batch_size=128, shuffle=True)"]},{"cell_type":"code","execution_count":10,"metadata":{"executionInfo":{"elapsed":2,"status":"ok","timestamp":1709251569354,"user":{"displayName":"Alan Chu","userId":"01538023754537267334"},"user_tz":360},"id":"0SFsOHJABDtM"},"outputs":[],"source":["# Training Procedure\n","def train(num_epoch, model, mini_trains, mini_vals, device, loss_function, optimizer):\n","  for epoch in range(num_epoch):\n","    num_iters = 0\n","    for x, y in mini_trains:\n","      model.train()\n","      x = x.to(device)\n","      y = y.to(device)\n","      scores = model(x)\n","      loss = loss_function(scores, y)\n","      optimizer.zero_grad()\n","      loss.backward()\n","      optimizer.step()\n","      if num_iters % 10 == 0:\n","        evaluate_predictor(model, epoch, mini_vals, device)\n","      num_iters += 1"]},{"cell_type":"code","execution_count":11,"metadata":{"executionInfo":{"elapsed":3,"status":"ok","timestamp":1709251569355,"user":{"displayName":"Alan Chu","userId":"01538023754537267334"},"user_tz":360},"id":"AGjktuIUBDvf"},"outputs":[],"source":["# Validating Procedure\n","def evaluate_predictor(model, epoch, mini_vals, device):\n","  model.eval()\n","  with torch.no_grad():\n","    acc_count = 0\n","    for x, y in mini_vals:\n","      x = x.to(device)\n","      y = y.to(device)\n","      scores=model(x)\n","      predictions=scores.max(1)[1]\n","      acc = predictions.eq(y).sum().item()\n","      acc_count += acc\n","    print(f'Epoch[{epoch+1}] Acc: {acc_count/num_val}')"]},{"cell_type":"code","execution_count":12,"metadata":{"executionInfo":{"elapsed":3,"status":"ok","timestamp":1709251569355,"user":{"displayName":"Alan Chu","userId":"01538023754537267334"},"user_tz":360},"id":"0V1SD_4pBDyH"},"outputs":[],"source":["# Define loss function \u0026 optimizer\n","import torch.optim as optim\n","loss_function = nn.CrossEntropyLoss()\n","optimizer = optim.Adam(model.parameters(), lr=1e-3)"]},{"cell_type":"code","execution_count":13,"metadata":{"colab":{"background_save":true,"base_uri":"https://localhost:8080/","height":339},"executionInfo":{"elapsed":153,"status":"error","timestamp":1709251569505,"user":{"displayName":"Alan Chu","userId":"01538023754537267334"},"user_tz":360},"id":"syDtanisBD0c"},"outputs":[{"name":"stderr","output_type":"stream","text":["ERROR:root:Internal Python error in the inspect module.\n","Below is the traceback from this internal error.\n","\n","ERROR:root:Internal Python error in the inspect module.\n","Below is the traceback from this internal error.\n","\n","ERROR:root:Internal Python error in the inspect module.\n","Below is the traceback from this internal error.\n","\n"]},{"name":"stdout","output_type":"stream","text":["Traceback (most recent call last):\n","  File \"/usr/local/lib/python3.10/dist-packages/IPython/core/interactiveshell.py\", line 3553, in run_code\n","    exec(code_obj, self.user_global_ns, self.user_ns)\n","  File \"\u003cipython-input-24-df9119c3ec53\u003e\", line 2, in \u003ccell line: 2\u003e\n","    train(1, model, mini_trains, mini_vals, device, loss_function, optimizer)\n","  File \"\u003cipython-input-21-130213b07839\u003e\", line 9, in train\n","    scores = model(x)\n","  File \"/usr/local/lib/python3.10/dist-packages/torch/nn/modules/module.py\", line 1518, in _wrapped_call_impl\n","    return self._call_impl(*args, **kwargs)\n","  File \"/usr/local/lib/python3.10/dist-packages/torch/nn/modules/module.py\", line 1527, in _call_impl\n","    return forward_call(*args, **kwargs)\n","  File \"\u003cipython-input-18-7d4a812f56f8\u003e\", line 29, in forward\n","    out = self.fc(out)\n","  File \"/usr/local/lib/python3.10/dist-packages/torch/nn/modules/module.py\", line 1518, in _wrapped_call_impl\n","    return self._call_impl(*args, **kwargs)\n","  File \"/usr/local/lib/python3.10/dist-packages/torch/nn/modules/module.py\", line 1527, in _call_impl\n","    return forward_call(*args, **kwargs)\n","  File \"/usr/local/lib/python3.10/dist-packages/torch/nn/modules/linear.py\", line 114, in forward\n","    return F.linear(input, self.weight, self.bias)\n","RuntimeError: mat1 and mat2 shapes cannot be multiplied (114688x14 and 12544x10)\n","\n","During handling of the above exception, another exception occurred:\n","\n","Traceback (most recent call last):\n","  File \"/usr/local/lib/python3.10/dist-packages/IPython/core/interactiveshell.py\", line 2099, in showtraceback\n","    stb = value._render_traceback_()\n","AttributeError: 'RuntimeError' object has no attribute '_render_traceback_'\n","\n","During handling of the above exception, another exception occurred:\n","\n","Traceback (most recent call last):\n","  File \"/usr/local/lib/python3.10/dist-packages/IPython/core/ultratb.py\", line 1101, in get_records\n","    return _fixed_getinnerframes(etb, number_of_lines_of_context, tb_offset)\n","  File \"/usr/local/lib/python3.10/dist-packages/IPython/core/ultratb.py\", line 248, in wrapped\n","    return f(*args, **kwargs)\n","  File \"/usr/local/lib/python3.10/dist-packages/IPython/core/ultratb.py\", line 281, in _fixed_getinnerframes\n","    records = fix_frame_records_filenames(inspect.getinnerframes(etb, context))\n","  File \"/usr/lib/python3.10/inspect.py\", line 1662, in getinnerframes\n","    frameinfo = (tb.tb_frame,) + getframeinfo(tb, context)\n","  File \"/usr/lib/python3.10/inspect.py\", line 1620, in getframeinfo\n","    filename = getsourcefile(frame) or getfile(frame)\n","  File \"/usr/lib/python3.10/inspect.py\", line 829, in getsourcefile\n","    module = getmodule(object, filename)\n","  File \"/usr/lib/python3.10/inspect.py\", line 861, in getmodule\n","    file = getabsfile(object, _filename)\n","  File \"/usr/lib/python3.10/inspect.py\", line 845, in getabsfile\n","    return os.path.normcase(os.path.abspath(_filename))\n","  File \"/usr/lib/python3.10/posixpath.py\", line 384, in abspath\n","    cwd = os.getcwd()\n","OSError: [Errno 107] Transport endpoint is not connected\n","Traceback (most recent call last):\n","  File \"/usr/local/lib/python3.10/dist-packages/IPython/core/interactiveshell.py\", line 3553, in run_code\n","    exec(code_obj, self.user_global_ns, self.user_ns)\n","  File \"\u003cipython-input-24-df9119c3ec53\u003e\", line 2, in \u003ccell line: 2\u003e\n","    train(1, model, mini_trains, mini_vals, device, loss_function, optimizer)\n","  File \"\u003cipython-input-21-130213b07839\u003e\", line 9, in train\n","    scores = model(x)\n","  File \"/usr/local/lib/python3.10/dist-packages/torch/nn/modules/module.py\", line 1518, in _wrapped_call_impl\n","    return self._call_impl(*args, **kwargs)\n","  File \"/usr/local/lib/python3.10/dist-packages/torch/nn/modules/module.py\", line 1527, in _call_impl\n","    return forward_call(*args, **kwargs)\n","  File \"\u003cipython-input-18-7d4a812f56f8\u003e\", line 29, in forward\n","    out = self.fc(out)\n","  File \"/usr/local/lib/python3.10/dist-packages/torch/nn/modules/module.py\", line 1518, in _wrapped_call_impl\n","    return self._call_impl(*args, **kwargs)\n","  File \"/usr/local/lib/python3.10/dist-packages/torch/nn/modules/module.py\", line 1527, in _call_impl\n","    return forward_call(*args, **kwargs)\n","  File \"/usr/local/lib/python3.10/dist-packages/torch/nn/modules/linear.py\", line 114, in forward\n","    return F.linear(input, self.weight, self.bias)\n","RuntimeError: mat1 and mat2 shapes cannot be multiplied (114688x14 and 12544x10)\n","\n","During handling of the above exception, another exception occurred:\n","\n","Traceback (most recent call last):\n","  File \"/usr/local/lib/python3.10/dist-packages/IPython/core/interactiveshell.py\", line 2099, in showtraceback\n","    stb = value._render_traceback_()\n","AttributeError: 'RuntimeError' object has no attribute '_render_traceback_'\n","\n","During handling of the above exception, another exception occurred:\n","\n","Traceback (most recent call last):\n","  File \"/usr/local/lib/python3.10/dist-packages/IPython/core/interactiveshell.py\", line 3473, in run_ast_nodes\n","    if (await self.run_code(code, result,  async_=asy)):\n","  File \"/usr/local/lib/python3.10/dist-packages/IPython/core/interactiveshell.py\", line 3575, in run_code\n","    self.showtraceback(running_compiled_code=True)\n","  File \"/usr/local/lib/python3.10/dist-packages/IPython/core/interactiveshell.py\", line 2101, in showtraceback\n","    stb = self.InteractiveTB.structured_traceback(etype,\n","  File \"/usr/local/lib/python3.10/dist-packages/IPython/core/ultratb.py\", line 1367, in structured_traceback\n","    return FormattedTB.structured_traceback(\n","  File \"/usr/local/lib/python3.10/dist-packages/IPython/core/ultratb.py\", line 1267, in structured_traceback\n","    return VerboseTB.structured_traceback(\n","  File \"/usr/local/lib/python3.10/dist-packages/IPython/core/ultratb.py\", line 1124, in structured_traceback\n","    formatted_exception = self.format_exception_as_a_whole(etype, evalue, etb, number_of_lines_of_context,\n","  File \"/usr/local/lib/python3.10/dist-packages/IPython/core/ultratb.py\", line 1082, in format_exception_as_a_whole\n","    last_unique, recursion_repeat = find_recursion(orig_etype, evalue, records)\n","  File \"/usr/local/lib/python3.10/dist-packages/IPython/core/ultratb.py\", line 382, in find_recursion\n","    return len(records), 0\n","TypeError: object of type 'NoneType' has no len()\n","\n","During handling of the above exception, another exception occurred:\n","\n","Traceback (most recent call last):\n","  File \"/usr/local/lib/python3.10/dist-packages/IPython/core/interactiveshell.py\", line 2099, in showtraceback\n","    stb = value._render_traceback_()\n","AttributeError: 'TypeError' object has no attribute '_render_traceback_'\n","\n","During handling of the above exception, another exception occurred:\n","\n","Traceback (most recent call last):\n","  File \"/usr/local/lib/python3.10/dist-packages/IPython/core/ultratb.py\", line 1101, in get_records\n","    return _fixed_getinnerframes(etb, number_of_lines_of_context, tb_offset)\n","  File \"/usr/local/lib/python3.10/dist-packages/IPython/core/ultratb.py\", line 248, in wrapped\n","    return f(*args, **kwargs)\n","  File \"/usr/local/lib/python3.10/dist-packages/IPython/core/ultratb.py\", line 281, in _fixed_getinnerframes\n","    records = fix_frame_records_filenames(inspect.getinnerframes(etb, context))\n","  File \"/usr/lib/python3.10/inspect.py\", line 1662, in getinnerframes\n","    frameinfo = (tb.tb_frame,) + getframeinfo(tb, context)\n","  File \"/usr/lib/python3.10/inspect.py\", line 1620, in getframeinfo\n","    filename = getsourcefile(frame) or getfile(frame)\n","  File \"/usr/lib/python3.10/inspect.py\", line 829, in getsourcefile\n","    module = getmodule(object, filename)\n","  File \"/usr/lib/python3.10/inspect.py\", line 861, in getmodule\n","    file = getabsfile(object, _filename)\n","  File \"/usr/lib/python3.10/inspect.py\", line 845, in getabsfile\n","    return os.path.normcase(os.path.abspath(_filename))\n","  File \"/usr/lib/python3.10/posixpath.py\", line 384, in abspath\n","    cwd = os.getcwd()\n","OSError: [Errno 107] Transport endpoint is not connected\n","Traceback (most recent call last):\n","  File \"/usr/local/lib/python3.10/dist-packages/IPython/core/interactiveshell.py\", line 3553, in run_code\n","    exec(code_obj, self.user_global_ns, self.user_ns)\n","  File \"\u003cipython-input-24-df9119c3ec53\u003e\", line 2, in \u003ccell line: 2\u003e\n","    train(1, model, mini_trains, mini_vals, device, loss_function, optimizer)\n","  File \"\u003cipython-input-21-130213b07839\u003e\", line 9, in train\n","    scores = model(x)\n","  File \"/usr/local/lib/python3.10/dist-packages/torch/nn/modules/module.py\", line 1518, in _wrapped_call_impl\n","    return self._call_impl(*args, **kwargs)\n","  File \"/usr/local/lib/python3.10/dist-packages/torch/nn/modules/module.py\", line 1527, in _call_impl\n","    return forward_call(*args, **kwargs)\n","  File \"\u003cipython-input-18-7d4a812f56f8\u003e\", line 29, in forward\n","    out = self.fc(out)\n","  File \"/usr/local/lib/python3.10/dist-packages/torch/nn/modules/module.py\", line 1518, in _wrapped_call_impl\n","    return self._call_impl(*args, **kwargs)\n","  File \"/usr/local/lib/python3.10/dist-packages/torch/nn/modules/module.py\", line 1527, in _call_impl\n","    return forward_call(*args, **kwargs)\n","  File \"/usr/local/lib/python3.10/dist-packages/torch/nn/modules/linear.py\", line 114, in forward\n","    return F.linear(input, self.weight, self.bias)\n","RuntimeError: mat1 and mat2 shapes cannot be multiplied (114688x14 and 12544x10)\n","\n","During handling of the above exception, another exception occurred:\n","\n","Traceback (most recent call last):\n","  File \"/usr/local/lib/python3.10/dist-packages/IPython/core/interactiveshell.py\", line 2099, in showtraceback\n","    stb = value._render_traceback_()\n","AttributeError: 'RuntimeError' object has no attribute '_render_traceback_'\n","\n","During handling of the above exception, another exception occurred:\n","\n","Traceback (most recent call last):\n","  File \"/usr/local/lib/python3.10/dist-packages/IPython/core/interactiveshell.py\", line 3473, in run_ast_nodes\n","    if (await self.run_code(code, result,  async_=asy)):\n","  File \"/usr/local/lib/python3.10/dist-packages/IPython/core/interactiveshell.py\", line 3575, in run_code\n","    self.showtraceback(running_compiled_code=True)\n","  File \"/usr/local/lib/python3.10/dist-packages/IPython/core/interactiveshell.py\", line 2101, in showtraceback\n","    stb = self.InteractiveTB.structured_traceback(etype,\n","  File \"/usr/local/lib/python3.10/dist-packages/IPython/core/ultratb.py\", line 1367, in structured_traceback\n","    return FormattedTB.structured_traceback(\n","  File \"/usr/local/lib/python3.10/dist-packages/IPython/core/ultratb.py\", line 1267, in structured_traceback\n","    return VerboseTB.structured_traceback(\n","  File \"/usr/local/lib/python3.10/dist-packages/IPython/core/ultratb.py\", line 1124, in structured_traceback\n","    formatted_exception = self.format_exception_as_a_whole(etype, evalue, etb, number_of_lines_of_context,\n","  File \"/usr/local/lib/python3.10/dist-packages/IPython/core/ultratb.py\", line 1082, in format_exception_as_a_whole\n","    last_unique, recursion_repeat = find_recursion(orig_etype, evalue, records)\n","  File \"/usr/local/lib/python3.10/dist-packages/IPython/core/ultratb.py\", line 382, in find_recursion\n","    return len(records), 0\n","TypeError: object of type 'NoneType' has no len()\n","\n","During handling of the above exception, another exception occurred:\n","\n","Traceback (most recent call last):\n","  File \"/usr/local/lib/python3.10/dist-packages/IPython/core/interactiveshell.py\", line 2099, in showtraceback\n","    stb = value._render_traceback_()\n","AttributeError: 'TypeError' object has no attribute '_render_traceback_'\n","\n","During handling of the above exception, another exception occurred:\n","\n","Traceback (most recent call last):\n","  File \"/usr/local/lib/python3.10/dist-packages/IPython/core/interactiveshell.py\", line 3030, in _run_cell\n","    return runner(coro)\n","  File \"/usr/local/lib/python3.10/dist-packages/IPython/core/async_helpers.py\", line 78, in _pseudo_sync_runner\n","    coro.send(None)\n","  File \"/usr/local/lib/python3.10/dist-packages/IPython/core/interactiveshell.py\", line 3257, in run_cell_async\n","    has_raised = await self.run_ast_nodes(code_ast.body, cell_name,\n","  File \"/usr/local/lib/python3.10/dist-packages/IPython/core/interactiveshell.py\", line 3492, in run_ast_nodes\n","    self.showtraceback()\n","  File \"/usr/local/lib/python3.10/dist-packages/IPython/core/interactiveshell.py\", line 2101, in showtraceback\n","    stb = self.InteractiveTB.structured_traceback(etype,\n","  File \"/usr/local/lib/python3.10/dist-packages/IPython/core/ultratb.py\", line 1367, in structured_traceback\n","    return FormattedTB.structured_traceback(\n","  File \"/usr/local/lib/python3.10/dist-packages/IPython/core/ultratb.py\", line 1267, in structured_traceback\n","    return VerboseTB.structured_traceback(\n","  File \"/usr/local/lib/python3.10/dist-packages/IPython/core/ultratb.py\", line 1142, in structured_traceback\n","    formatted_exceptions += self.format_exception_as_a_whole(etype, evalue, etb, lines_of_context,\n","  File \"/usr/local/lib/python3.10/dist-packages/IPython/core/ultratb.py\", line 1082, in format_exception_as_a_whole\n","    last_unique, recursion_repeat = find_recursion(orig_etype, evalue, records)\n","  File \"/usr/local/lib/python3.10/dist-packages/IPython/core/ultratb.py\", line 382, in find_recursion\n","    return len(records), 0\n","TypeError: object of type 'NoneType' has no len()\n","\n","During handling of the above exception, another exception occurred:\n","\n","Traceback (most recent call last):\n","  File \"/usr/local/lib/python3.10/dist-packages/IPython/core/interactiveshell.py\", line 2099, in showtraceback\n","    stb = value._render_traceback_()\n","AttributeError: 'TypeError' object has no attribute '_render_traceback_'\n","\n","During handling of the above exception, another exception occurred:\n","\n","Traceback (most recent call last):\n","  File \"/usr/local/lib/python3.10/dist-packages/IPython/core/ultratb.py\", line 1101, in get_records\n","    return _fixed_getinnerframes(etb, number_of_lines_of_context, tb_offset)\n","  File \"/usr/local/lib/python3.10/dist-packages/IPython/core/ultratb.py\", line 248, in wrapped\n","    return f(*args, **kwargs)\n","  File \"/usr/local/lib/python3.10/dist-packages/IPython/core/ultratb.py\", line 281, in _fixed_getinnerframes\n","    records = fix_frame_records_filenames(inspect.getinnerframes(etb, context))\n","  File \"/usr/lib/python3.10/inspect.py\", line 1662, in getinnerframes\n","    frameinfo = (tb.tb_frame,) + getframeinfo(tb, context)\n","  File \"/usr/lib/python3.10/inspect.py\", line 1620, in getframeinfo\n","    filename = getsourcefile(frame) or getfile(frame)\n","  File \"/usr/lib/python3.10/inspect.py\", line 829, in getsourcefile\n","    module = getmodule(object, filename)\n","  File \"/usr/lib/python3.10/inspect.py\", line 861, in getmodule\n","    file = getabsfile(object, _filename)\n","  File \"/usr/lib/python3.10/inspect.py\", line 845, in getabsfile\n","    return os.path.normcase(os.path.abspath(_filename))\n","  File \"/usr/lib/python3.10/posixpath.py\", line 384, in abspath\n","    cwd = os.getcwd()\n","OSError: [Errno 107] Transport endpoint is not connected\n"]}],"source":["# Start training\n","train(1, model, mini_trains, mini_vals, device, loss_function, optimizer)"]}],"metadata":{"accelerator":"GPU","colab":{"name":"","version":""},"gpuClass":"standard","kernelspec":{"display_name":"Python 3","language":"python","name":"python3"},"language_info":{"codemirror_mode":{"name":"ipython","version":3},"file_extension":".py","mimetype":"text/x-python","name":"python","nbconvert_exporter":"python","pygments_lexer":"ipython3","version":"3.8.5"}},"nbformat":4,"nbformat_minor":0}